Workbook

Sheet League Table
A1: Rank | B1: Name | C1: ELO | D1: Peak ELO | E1: Games | F1: Wins | G1: Draws | H1: Losses | I1: Win % | J1: BP | K1: Tournaments Played
A2: =IF(ROW()-1<=COUNTA('Player Data'!$A$2:$A$51),ROW()-1,"") -> 1 | B2: =IFERROR(INDEX('Player Data'!$A$2:$A$51,MATCH(ROW()-1,'Player Data'!$L$2:$L$51,0)),"") -> John | C2: =IFERROR(INDEX('Player Data'!$B$2:$B$51,MATCH(ROW()-1,'Player Data'!$L$2:$L$51,0)),"") -> 1072 | D2: =IFERROR(INDEX('Player Data'!$C$2:$C$51,MATCH(ROW()-1,'Player Data'!$L$2:$L$51,0)),"") -> 1072 | E2: =IFERROR(INDEX('Player Data'!$D$2:$D$51,MATCH(ROW()-1,'Player Data'!$L$2:$L$51,0)),"") -> 11 | F2: =IFERROR(INDEX('Player Data'!$E$2:$E$51,MATCH(ROW()-1,'Player Data'!$L$2:$L$51,0)),"") -> 7 | G2: =IFERROR(INDEX('Player Data'!$F$2:$F$51,MATCH(ROW()-1,'Player Data'!$L$2:$L$51,0)),"") -> 1 | H2: =IFERROR(INDEX('Player Data'!$G$2:$G$51,MATCH(ROW()-1,'Player Data'!$L$2:$L$51,0)),"") -> 3 | I2: =IFERROR(INDEX('Player Data'!$I$2:$I$51,MATCH(ROW()-1,'Player Data'!$L$2:$L$51,0)),"") -> 0.63636364 | J2: =IFERROR(INDEX('Player Data'!$H$2:$H$51,MATCH(ROW()-1,'Player Data'!$L$2:$L$51,0)),"") -> 937 | K2: =IF(B2="","",COUNTIF('Tournament Log'!C:C,B2)) -> 1
A3: =IF(ROW()-1<=COUNTA('Player Data'!$A$2:$A$51),ROW()-1,"") -> 2 | B3: =IFERROR(INDEX('Player Data'!$A$2:$A$51,MATCH(ROW()-1,'Player Data'!$L$2:$L$51,0)),"") -> Gav | C3: =IFERROR(INDEX('Player Data'!$B$2:$B$51,MATCH(ROW()-1,'Player Data'!$L$2:$L$51,0)),"") -> 1019 | D3: =IFERROR(INDEX('Player Data'!$C$2:$C$51,MATCH(ROW()-1,'Player Data'!$L$2:$L$51,0)),"") -> 1037 | E3: =IFERROR(INDEX('Player Data'!$D$2:$D$51,MATCH(ROW()-1,'Player Data'!$L$2:$L$51,0)),"") -> 7 | F3: =IFERROR(INDEX('Player Data'!$E$2:$E$51,MATCH(ROW()-1,'Player Data'!$L$2:$L$51,0)),"") -> 4 | G3: =IFERROR(INDEX('Player Data'!$F$2:$F$51,MATCH(ROW()-1,'Player Data'!$L$2:$L$51,0)),"") -> 0 | H3: =IFERROR(INDEX('Player Data'!$G$2:$G$51,MATCH(ROW()-1,'Player Data'!$L$2:$L$51,0)),"") -> 3 | I3: =IFERROR(INDEX('Player Data'!$I$2:$I$51,MATCH(ROW()-1,'Player Data'!$L$2:$L$51,0)),"") -> 0.57142857 | J3: =IFERROR(INDEX('Player Data'!$H$2:$H$51,MATCH(ROW()-1,'Player Data'!$L$2:$L$51,0)),"") -> 539 | K3: =IF(B3="","",COUNTIF('Tournament Log'!C:C,B3)) -> 1
A4: =IF(ROW()-1<=COUNTA('Player Data'!$A$2:$A$51),ROW()-1,"") -> 3 | B4: =IFERROR(INDEX('Player Data'!$A$2:$A$51,MATCH(ROW()-1,'Player Data'!$L$2:$L$51,0)),"") -> Allan | C4: =IFERROR(INDEX('Player Data'!$B$2:$B$51,MATCH(ROW()-1,'Player Data'!$L$2:$L$51,0)),"") -> 1017 | D4: =IFERROR(INDEX('Player Data'!$C$2:$C$51,MATCH(ROW()-1,'Player Data'!$L$2:$L$51,0)),"") -> 1017 | E4: =IFERROR(INDEX('Player Data'!$D$2:$D$51,MATCH(ROW()-1,'Player Data'!$L$2:$L$51,0)),"") -> 2 | F4: =IFERROR(INDEX('Player Data'!$E$2:$E$51,MATCH(ROW()-1,'Player Data'!$L$2:$L$51,0)),"") -> 2 | G4: =IFERROR(INDEX('Player Data'!$F$2:$F$51,MATCH(ROW()-1,'Player Data'!$L$2:$L$51,0)),"") -> 0 | H4: =IFERROR(INDEX('Player Data'!$G$2:$G$51,MATCH(ROW()-1,'Player Data'!$L$2:$L$51,0)),"") -> 0 | I4: =IFERROR(INDEX('Player Data'!$I$2:$I$51,MATCH(ROW()-1,'Player Data'!$L$2:$L$51,0)),"") -> 1 | J4: =IFERROR(INDEX('Player Data'!$H$2:$H$51,MATCH(ROW()-1,'Player Data'!$L$2:$L$51,0)),"") -> 187 | K4: =IF(B4="","",COUNTIF('Tournament Log'!C:C,B4)) -> 0
A5: =IF(ROW()-1<=COUNTA('Player Data'!$A$2:$A$51),ROW()-1,"") -> 4 | B5: =IFERROR(INDEX('Player Data'!$A$2:$A$51,MATCH(ROW()-1,'Player Data'!$L$2:$L$51,0)),"") -> Ryan | C5: =IFERROR(INDEX('Player Data'!$B$2:$B$51,MATCH(ROW()-1,'Player Data'!$L$2:$L$51,0)),"") -> 1016 | D5: =IFERROR(INDEX('Player Data'!$C$2:$C$51,MATCH(ROW()-1,'Player Data'!$L$2:$L$51,0)),"") -> 1016 | E5: =IFERROR(INDEX('Player Data'!$D$2:$D$51,MATCH(ROW()-1,'Player Data'!$L$2:$L$51,0)),"") -> 1 | F5: =IFERROR(INDEX('Player Data'!$E$2:$E$51,MATCH(ROW()-1,'Player Data'!$L$2:$L$51,0)),"") -> 1 | G5: =IFERROR(INDEX('Player Data'!$F$2:$F$51,MATCH(ROW()-1,'Player Data'!$L$2:$L$51,0)),"") -> 0 | H5: =IFERROR(INDEX('Player Data'!$G$2:$G$51,MATCH(ROW()-1,'Player Data'!$L$2:$L$51,0)),"") -> 0 | I5: =IFERROR(INDEX('Player Data'!$I$2:$I$51,MATCH(ROW()-1,'Player Data'!$L$2:$L$51,0)),"") -> 1 | J5: =IFERROR(INDEX('Player Data'!$H$2:$H$51,MATCH(ROW()-1,'Player Data'!$L$2:$L$51,0)),"") -> 58 | K5: =IF(B5="","",COUNTIF('Tournament Log'!C:C,B5)) -> 0
A6: =IF(ROW()-1<=COUNTA('Player Data'!$A$2:$A$51),ROW()-1,"") -> 5 | B6: =IFERROR(INDEX('Player Data'!$A$2:$A$51,MATCH(ROW()-1,'Player Data'!$L$2:$L$51,0)),"") -> Pete | C6: =IFERROR(INDEX('Player Data'!$B$2:$B$51,MATCH(ROW()-1,'Player Data'!$L$2:$L$51,0)),"") -> 1015 | D6: =IFERROR(INDEX('Player Data'!$C$2:$C$51,MATCH(ROW()-1,'Player Data'!$L$2:$L$51,0)),"") -> 1015 | E6: =IFERROR(INDEX('Player Data'!$D$2:$D$51,MATCH(ROW()-1,'Player Data'!$L$2:$L$51,0)),"") -> 1 | F6: =IFERROR(INDEX('Player Data'!$E$2:$E$51,MATCH(ROW()-1,'Player Data'!$L$2:$L$51,0)),"") -> 1 | G6: =IFERROR(INDEX('Player Data'!$F$2:$F$51,MATCH(ROW()-1,'Player Data'!$L$2:$L$51,0)),"") -> 0 | H6: =IFERROR(INDEX('Player Data'!$G$2:$G$51,MATCH(ROW()-1,'Player Data'!$L$2:$L$51,0)),"") -> 0 | I6: =IFERROR(INDEX('Player Data'!$I$2:$I$51,MATCH(ROW()-1,'Player Data'!$L$2:$L$51,0)),"") -> 1 | J6: =IFERROR(INDEX('Player Data'!$H$2:$H$51,MATCH(ROW()-1,'Player Data'!$L$2:$L$51,0)),"") -> 40 | K6: =IF(B6="","",COUNTIF('Tournament Log'!C:C,B6)) -> 0
A7: =IF(ROW()-1<=COUNTA('Player Data'!$A$2:$A$51),ROW()-1,"") -> 6 | B7: =IFERROR(INDEX('Player Data'!$A$2:$A$51,MATCH(ROW()-1,'Player Data'!$L$2:$L$51,0)),"") -> Miles | C7: =IFERROR(INDEX('Player Data'!$B$2:$B$51,MATCH(ROW()-1,'Player Data'!$L$2:$L$51,0)),"") -> 1012 | D7: =IFERROR(INDEX('Player Data'!$C$2:$C$51,MATCH(ROW()-1,'Player Data'!$L$2:$L$51,0)),"") -> 1032 | E7: =IFERROR(INDEX('Player Data'!$D$2:$D$51,MATCH(ROW()-1,'Player Data'!$L$2:$L$51,0)),"") -> 5 | F7: =IFERROR(INDEX('Player Data'!$E$2:$E$51,MATCH(ROW()-1,'Player Data'!$L$2:$L$51,0)),"") -> 3 | G7: =IFERROR(INDEX('Player Data'!$F$2:$F$51,MATCH(ROW()-1,'Player Data'!$L$2:$L$51,0)),"") -> 0 | H7: =IFERROR(INDEX('Player Data'!$G$2:$G$51,MATCH(ROW()-1,'Player Data'!$L$2:$L$51,0)),"") -> 2 | I7: =IFERROR(INDEX('Player Data'!$I$2:$I$51,MATCH(ROW()-1,'Player Data'!$L$2:$L$51,0)),"") -> 0.6 | J7: =IFERROR(INDEX('Player Data'!$H$2:$H$51,MATCH(ROW()-1,'Player Data'!$L$2:$L$51,0)),"") -> 424 | K7: =IF(B7="","",COUNTIF('Tournament Log'!C:C,B7)) -> 0
A8: =IF(ROW()-1<=COUNTA('Player Data'!$A$2:$A$51),ROW()-1,"") -> 7 | B8: =IFERROR(INDEX('Player Data'!$A$2:$A$51,MATCH(ROW()-1,'Player Data'!$L$2:$L$51,0)),"") -> Andrew | C8: =IFERROR(INDEX('Player Data'!$B$2:$B$51,MATCH(ROW()-1,'Player Data'!$L$2:$L$51,0)),"") -> 1011 | D8: =IFERROR(INDEX('Player Data'!$C$2:$C$51,MATCH(ROW()-1,'Player Data'!$L$2:$L$51,0)),"") -> 1011 | E8: =IFERROR(INDEX('Player Data'!$D$2:$D$51,MATCH(ROW()-1,'Player Data'!$L$2:$L$51,0)),"") -> 13 | F8: =IFERROR(INDEX('Player Data'!$E$2:$E$51,MATCH(ROW()-1,'Player Data'!$L$2:$L$51,0)),"") -> 6 | G8: =IFERROR(INDEX('Player Data'!$F$2:$F$51,MATCH(ROW()-1,'Player Data'!$L$2:$L$51,0)),"") -> 0 | H8: =IFERROR(INDEX('Player Data'!$G$2:$G$51,MATCH(ROW()-1,'Player Data'!$L$2:$L$51,0)),"") -> 7 | I8: =IFERROR(INDEX('Player Data'!$I$2:$I$51,MATCH(ROW()-1,'Player Data'!$L$2:$L$51,0)),"") -> 0.46153846 | J8: =IFERROR(INDEX('Player Data'!$H$2:$H$51,MATCH(ROW()-1,'Player Data'!$L$2:$L$51,0)),"") -> 1053 | K8: =IF(B8="","",COUNTIF('Tournament Log'!C:C,B8)) -> 1
A9: =IF(ROW()-1<=COUNTA('Player Data'!$A$2:$A$51),ROW()-1,"") -> 8 | B9: =IFERROR(INDEX('Player Data'!$A$2:$A$51,MATCH(ROW()-1,'Player Data'!$L$2:$L$51,0)),"") -> Colin | C9: =IFERROR(INDEX('Player Data'!$B$2:$B$51,MATCH(ROW()-1,'Player Data'!$L$2:$L$51,0)),"") -> 985 | D9: =IFERROR(INDEX('Player Data'!$C$2:$C$51,MATCH(ROW()-1,'Player Data'!$L$2:$L$51,0)),"") -> 1029 | E9: =IFERROR(INDEX('Player Data'!$D$2:$D$51,MATCH(ROW()-1,'Player Data'!$L$2:$L$51,0)),"") -> 16 | F9: =IFERROR(INDEX('Player Data'!$E$2:$E$51,MATCH(ROW()-1,'Player Data'!$L$2:$L$51,0)),"") -> 7 | G9: =IFERROR(INDEX('Player Data'!$F$2:$F$51,MATCH(ROW()-1,'Player Data'!$L$2:$L$51,0)),"") -> 1 | H9: =IFERROR(INDEX('Player Data'!$G$2:$G$51,MATCH(ROW()-1,'Player Data'!$L$2:$L$51,0)),"") -> 8 | I9: =IFERROR(INDEX('Player Data'!$I$2:$I$51,MATCH(ROW()-1,'Player Data'!$L$2:$L$51,0)),"") -> 0.4375 | J9: =IFERROR(INDEX('Player Data'!$H$2:$H$51,MATCH(ROW()-1,'Player Data'!$L$2:$L$51,0)),"") -> 1339 | K9: =IF(B9="","",COUNTIF('Tournament Log'!C:C,B9)) -> 0
A10: =IF(ROW()-1<=COUNTA('Player Data'!$A$2:$A$51),ROW()-1,"") -> 9 | B10: =IFERROR(INDEX('Player Data'!$A$2:$A$51,MATCH(ROW()-1,'Player Data'!$L$2:$L$51,0)),"") -> Brett | C10: =IFERROR(INDEX('Player Data'!$B$2:$B$51,MATCH(ROW()-1,'Player Data'!$L$2:$L$51,0)),"") -> 958 | D10: =IFERROR(INDEX('Player Data'!$C$2:$C$51,MATCH(ROW()-1,'Player Data'!$L$2:$L$51,0)),"") -> 1000 | E10: =IFERROR(INDEX('Player Data'!$D$2:$D$51,MATCH(ROW()-1,'Player Data'!$L$2:$L$51,0)),"") -> 5 | F10: =IFERROR(INDEX('Player Data'!$E$2:$E$51,MATCH(ROW()-1,'Player Data'!$L$2:$L$51,0)),"") -> 1 | G10: =IFERROR(INDEX('Player Data'!$F$2:$F$51,MATCH(ROW()-1,'Player Data'!$L$2:$L$51,0)),"") -> 0 | H10: =IFERROR(INDEX('Player Data'!$G$2:$G$51,MATCH(ROW()-1,'Player Data'!$L$2:$L$51,0)),"") -> 4 | I10: =IFERROR(INDEX('Player Data'!$I$2:$I$51,MATCH(ROW()-1,'Player Data'!$L$2:$L$51,0)),"") -> 0.2 | J10: =IFERROR(INDEX('Player Data'!$H$2:$H$51,MATCH(ROW()-1,'Player Data'!$L$2:$L$51,0)),"") -> 347 | K10: =IF(B10="","",COUNTIF('Tournament Log'!C:C,B10)) -> 0
A11: =IF(ROW()-1<=COUNTA('Player Data'!$A$2:$A$51),ROW()-1,"") -> 10 | B11: =IFERROR(INDEX('Player Data'!$A$2:$A$51,MATCH(ROW()-1,'Player Data'!$L$2:$L$51,0)),"") -> Kev | C11: =IFERROR(INDEX('Player Data'!$B$2:$B$51,MATCH(ROW()-1,'Player Data'!$L$2:$L$51,0)),"") -> 957 | D11: =IFERROR(INDEX('Player Data'!$C$2:$C$51,MATCH(ROW()-1,'Player Data'!$L$2:$L$51,0)),"") -> 1000 | E11: =IFERROR(INDEX('Player Data'!$D$2:$D$51,MATCH(ROW()-1,'Player Data'!$L$2:$L$51,0)),"") -> 3 | F11: =IFERROR(INDEX('Player Data'!$E$2:$E$51,MATCH(ROW()-1,'Player Data'!$L$2:$L$51,0)),"") -> 0 | G11: =IFERROR(INDEX('Player Data'!$F$2:$F$51,MATCH(ROW()-1,'Player Data'!$L$2:$L$51,0)),"") -> 0 | H11: =IFERROR(INDEX('Player Data'!$G$2:$G$51,MATCH(ROW()-1,'Player Data'!$L$2:$L$51,0)),"") -> 3 | I11: =IFERROR(INDEX('Player Data'!$I$2:$I$51,MATCH(ROW()-1,'Player Data'!$L$2:$L$51,0)),"") -> 0 | J11: =IFERROR(INDEX('Player Data'!$H$2:$H$51,MATCH(ROW()-1,'Player Data'!$L$2:$L$51,0)),"") -> 135 | K11: =IF(B11="","",COUNTIF('Tournament Log'!C:C,B11)) -> 0
A12: =IF(ROW()-1<=COUNTA('Player Data'!$A$2:$A$51),ROW()-1,"") | B12: =IFERROR(INDEX('Player Data'!$A$2:$A$51,MATCH(ROW()-1,'Player Data'!$L$2:$L$51,0)),"") | C12: =IFERROR(INDEX('Player Data'!$B$2:$B$51,MATCH(ROW()-1,'Player Data'!$L$2:$L$51,0)),"") | D12: =IFERROR(INDEX('Player Data'!$C$2:$C$51,MATCH(ROW()-1,'Player Data'!$L$2:$L$51,0)),"") | E12: =IFERROR(INDEX('Player Data'!$D$2:$D$51,MATCH(ROW()-1,'Player Data'!$L$2:$L$51,0)),"") | F12: =IFERROR(INDEX('Player Data'!$E$2:$E$51,MATCH(ROW()-1,'Player Data'!$L$2:$L$51,0)),"") | G12: =IFERROR(INDEX('Player Data'!$F$2:$F$51,MATCH(ROW()-1,'Player Data'!$L$2:$L$51,0)),"") | H12: =IFERROR(INDEX('Player Data'!$G$2:$G$51,MATCH(ROW()-1,'Player Data'!$L$2:$L$51,0)),"") | I12: =IFERROR(INDEX('Player Data'!$I$2:$I$51,MATCH(ROW()-1,'Player Data'!$L$2:$L$51,0)),"") | J12: =IFERROR(INDEX('Player Data'!$H$2:$H$51,MATCH(ROW()-1,'Player Data'!$L$2:$L$51,0)),"") | K12: =IF(B12="","",COUNTIF('Tournament Log'!C:C,B12))
A13: =IF(ROW()-1<=COUNTA('Player Data'!$A$2:$A$51),ROW()-1,"") | B13: =IFERROR(INDEX('Player Data'!$A$2:$A$51,MATCH(ROW()-1,'Player Data'!$L$2:$L$51,0)),"") | C13: =IFERROR(INDEX('Player Data'!$B$2:$B$51,MATCH(ROW()-1,'Player Data'!$L$2:$L$51,0)),"") | D13: =IFERROR(INDEX('Player Data'!$C$2:$C$51,MATCH(ROW()-1,'Player Data'!$L$2:$L$51,0)),"") | E13: =IFERROR(INDEX('Player Data'!$D$2:$D$51,MATCH(ROW()-1,'Player Data'!$L$2:$L$51,0)),"") | F13: =IFERROR(INDEX('Player Data'!$E$2:$E$51,MATCH(ROW()-1,'Player Data'!$L$2:$L$51,0)),"") | G13: =IFERROR(INDEX('Player Data'!$F$2:$F$51,MATCH(ROW()-1,'Player Data'!$L$2:$L$51,0)),"") | H13: =IFERROR(INDEX('Player Data'!$G$2:$G$51,MATCH(ROW()-1,'Player Data'!$L$2:$L$51,0)),"") | I13: =IFERROR(INDEX('Player Data'!$I$2:$I$51,MATCH(ROW()-1,'Player Data'!$L$2:$L$51,0)),"") | J13: =IFERROR(INDEX('Player Data'!$H$2:$H$51,MATCH(ROW()-1,'Player Data'!$L$2:$L$51,0)),"") | K13: =IF(B13="","",COUNTIF('Tournament Log'!C:C,B13))
... A51: =IF(ROW()-1<=COUNTA('Player Data'!$A$2:$A$51),ROW()-1,"") | B51: =IFERROR(INDEX('Player Data'!$A$2:$A$51,MATCH(ROW()-1,'Player Data'!$L$2:$L$51,0)),"") | C51: =IFERROR(INDEX('Player Data'!$B$2:$B$51,MATCH(ROW()-1,'Player Data'!$L$2:$L$51,0)),"") | D51: =IFERROR(INDEX('Player Data'!$C$2:$C$51,MATCH(ROW()-1,'Player Data'!$L$2:$L$51,0)),"") | E51: =IFERROR(INDEX('Player Data'!$D$2:$D$51,MATCH(ROW()-1,'Player Data'!$L$2:$L$51,0)),"") | F51: =IFERROR(INDEX('Player Data'!$E$2:$E$51,MATCH(ROW()-1,'Player Data'!$L$2:$L$51,0)),"") | G51: =IFERROR(INDEX('Player Data'!$F$2:$F$51,MATCH(ROW()-1,'Player Data'!$L$2:$L$51,0)),"") | H51: =IFERROR(INDEX('Player Data'!$G$2:$G$51,MATCH(ROW()-1,'Player Data'!$L$2:$L$51,0)),"") | I51: =IFERROR(INDEX('Player Data'!$I$2:$I$51,MATCH(ROW()-1,'Player Data'!$L$2:$L$51,0)),"") | J51: =IFERROR(INDEX('Player Data'!$H$2:$H$51,MATCH(ROW()-1,'Player Data'!$L$2:$L$51,0)),"") | K51: =IF(B51="","",COUNTIF('Tournament Log'!C:C,B51))

Sheet Match Log
A1: MATCH LOG — Record each game result here (one row per game)
A2: Date | B2: Player 1 | C2: Player 2 | D2: Result (P1 perspective) | E2: BP P1 | F2: BP P2 | G2: P1 Faction | H2: P2 Faction | I2: Notes | J2: Sort Key (auto) | K2: Chrono Rank (auto)
A3: 46190 | B3: Andrew | C3: Colin | D3: Loss | E3: 65 | F3: 97 | G3: Necrons | H3: Death Guard | J3: =IF(A3="","",A3+ROW()/10000000) -> 46190 | K3: =IF(J3="","",COUNTIF($J$3:$J$501,"<"&J3)+COUNTIF('Tournament Log'!$N$4:$N$203,"<"&J3)+COUNTIF('Guest Log'!$K$4:$K$203,"<"&J3)+1) -> 1
A4: 46193 | B4: Andrew | C4: Colin | D4: Win | E4: 91 | F4: 80 | G4: Necrons | H4: Death Guard | J4: =IF(A4="","",A4+ROW()/10000000) -> 46193 | K4: =IF(J4="","",COUNTIF($J$3:$J$501,"<"&J4)+COUNTIF('Tournament Log'!$N$4:$N$203,"<"&J4)+COUNTIF('Guest Log'!$K$4:$K$203,"<"&J4)+1) -> 2
A5: 46193 | B5: Andrew | C5: Miles | D5: Loss | E5: 77 | F5: 88 | G5: Necrons | H5: GSC | J5: =IF(A5="","",A5+ROW()/10000000) -> 46193 | K5: =IF(J5="","",COUNTIF($J$3:$J$501,"<"&J5)+COUNTIF('Tournament Log'!$N$4:$N$203,"<"&J5)+COUNTIF('Guest Log'!$K$4:$K$203,"<"&J5)+1) -> 3
A6: 46193 | B6: John | C6: Colin | D6: Win | E6: 91 | F6: 69 | G6: Blood Angels | H6: Death Guard | J6: =IF(A6="","",A6+ROW()/10000000) -> 46193 | K6: =IF(J6="","",COUNTIF($J$3:$J$501,"<"&J6)+COUNTIF('Tournament Log'!$N$4:$N$203,"<"&J6)+COUNTIF('Guest Log'!$K$4:$K$203,"<"&J6)+1) -> 4
A7: 46195 | B7: Brett | C7: Colin | D7: Loss | E7: 69 | F7: 70 | G7: Orks | H7: Death Guard | J7: =IF(A7="","",A7+ROW()/10000000) -> 46195 | K7: =IF(J7="","",COUNTIF($J$3:$J$501,"<"&J7)+COUNTIF('Tournament Log'!$N$4:$N$203,"<"&J7)+COUNTIF('Guest Log'!$K$4:$K$203,"<"&J7)+1) -> 5
A8: 46196 | B8: Andrew | C8: Colin | D8: Loss | E8: 77 | F8: 85 | G8: Necrons | H8: Death Guard | J8: =IF(A8="","",A8+ROW()/10000000) -> 46196 | K8: =IF(J8="","",COUNTIF($J$3:$J$501,"<"&J8)+COUNTIF('Tournament Log'!$N$4:$N$203,"<"&J8)+COUNTIF('Guest Log'!$K$4:$K$203,"<"&J8)+1) -> 6
A9: 46202 | B9: Gav | C9: Brett | D9: Win | E9: 93 | F9: 37 | G9: Votaan | H9: Orks | J9: =IF(A9="","",A9+ROW()/10000000) -> 46202 | K9: =IF(J9="","",COUNTIF($J$3:$J$501,"<"&J9)+COUNTIF('Tournament Log'!$N$4:$N$203,"<"&J9)+COUNTIF('Guest Log'!$K$4:$K$203,"<"&J9)+1) -> 10
A10: 46203 | B10: Andrew | C10: Colin | D10: Loss | E10: 59 | F10: 86 | G10: Necrons | H10: Death Guard | J10: =IF(A10="","",A10+ROW()/10000000) -> 46203 | K10: =IF(J10="","",COUNTIF($J$3:$J$501,"<"&J10)+COUNTIF('Tournament Log'!$N$4:$N$203,"<"&J10)+COUNTIF('Guest Log'!$K$4:$K$203,"<"&J10)+1) -> 11
A11: 46204 | B11: John | C11: Colin | D11: Win | E11: 97 | F11: 78 | G11: Blood Angels | H11: Death Guard | J11: =IF(A11="","",A11+ROW()/10000000) -> 46204 | K11: =IF(J11="","",COUNTIF($J$3:$J$501,"<"&J11)+COUNTIF('Tournament Log'!$N$4:$N$203,"<"&J11)+COUNTIF('Guest Log'!$K$4:$K$203,"<"&J11)+1) -> 12
A12: 46205 | B12: Andrew | C12: Brett | D12: Win | E12: 86 | F12: 69 | G12: Necrons | H12: Orks | J12: =IF(A12="","",A12+ROW()/10000000) -> 46205 | K12: =IF(J12="","",COUNTIF($J$3:$J$501,"<"&J12)+COUNTIF('Tournament Log'!$N$4:$N$203,"<"&J12)+COUNTIF('Guest Log'!$K$4:$K$203,"<"&J12)+1) -> 13
A13: 46209 | B13: Colin | C13: Miles | D13: Loss | E13: 90 | F13: 94 | G13: Death Guard | H13: Imperial Knights | J13: =IF(A13="","",A13+ROW()/10000000) -> 46209 | K13: =IF(J13="","",COUNTIF($J$3:$J$501,"<"&J13)+COUNTIF('Tournament Log'!$N$4:$N$203,"<"&J13)+COUNTIF('Guest Log'!$K$4:$K$203,"<"&J13)+1) -> 14
A14: 46210 | B14: Andrew | C14: Colin | D14: Loss | E14: 74 | F14: 81 | G14: Necrons | H14: Death Guard | J14: =IF(A14="","",A14+ROW()/10000000) -> 46210 | K14: =IF(J14="","",COUNTIF($J$3:$J$501,"<"&J14)+COUNTIF('Tournament Log'!$N$4:$N$203,"<"&J14)+COUNTIF('Guest Log'!$K$4:$K$203,"<"&J14)+1) -> 15
... A28: 46364 | B28: John | C28: Brett | D28: Win | E28: 83 | F28: 82 | G28: Blood Angels | H28: Orks | J28: =IF(A28="","",A28+ROW()/10000000) -> 46364 | K28: =IF(J28="","",COUNTIF($J$3:$J$501,"<"&J28)+COUNTIF('Tournament Log'!$N$4:$N$203,"<"&J28)+COUNTIF('Guest Log'!$K$4:$K$203,"<"&J28)+1) -> 29
J29: =IF(A29="","",A29+ROW()/10000000) | K29: =IF(J29="","",COUNTIF($J$3:$J$501,"<"&J29)+COUNTIF('Tournament Log'!$N$4:$N$203,"<"&J29)+COUNTIF('Guest Log'!$K$4:$K$203,"<"&J29)+1)
J30: =IF(A30="","",A30+ROW()/10000000) | K30: =IF(J30="","",COUNTIF($J$3:$J$501,"<"&J30)+COUNTIF('Tournament Log'!$N$4:$N$203,"<"&J30)+COUNTIF('Guest Log'!$K$4:$K$203,"<"&J30)+1)
J31: =IF(A31="","",A31+ROW()/10000000) | K31: =IF(J31="","",COUNTIF($J$3:$J$501,"<"&J31)+COUNTIF('Tournament Log'!$N$4:$N$203,"<"&J31)+COUNTIF('Guest Log'!$K$4:$K$203,"<"&J31)+1)
J32: =IF(A32="","",A32+ROW()/10000000) | K32: =IF(J32="","",COUNTIF($J$3:$J$501,"<"&J32)+COUNTIF('Tournament Log'!$N$4:$N$203,"<"&J32)+COUNTIF('Guest Log'!$K$4:$K$203,"<"&J32)+1)
J33: =IF(A33="","",A33+ROW()/10000000) | K33: =IF(J33="","",COUNTIF($J$3:$J$501,"<"&J33)+COUNTIF('Tournament Log'!$N$4:$N$203,"<"&J33)+COUNTIF('Guest Log'!$K$4:$K$203,"<"&J33)+1)
J34: =IF(A34="","",A34+ROW()/10000000) | K34: =IF(J34="","",COUNTIF($J$3:$J$501,"<"&J34)+COUNTIF('Tournament Log'!$N$4:$N$203,"<"&J34)+COUNTIF('Guest Log'!$K$4:$K$203,"<"&J34)+1)
J35: =IF(A35="","",A35+ROW()/10000000) | K35: =IF(J35="","",COUNTIF($J$3:$J$501,"<"&J35)+COUNTIF('Tournament Log'!$N$4:$N$203,"<"&J35)+COUNTIF('Guest Log'!$K$4:$K$203,"<"&J35)+1)
J36: =IF(A36="","",A36+ROW()/10000000) | K36: =IF(J36="","",COUNTIF($J$3:$J$501,"<"&J36)+COUNTIF('Tournament Log'!$N$4:$N$203,"<"&J36)+COUNTIF('Guest Log'!$K$4:$K$203,"<"&J36)+1)
J37: =IF(A37="","",A37+ROW()/10000000) | K37: =IF(J37="","",COUNTIF($J$3:$J$501,"<"&J37)+COUNTIF('Tournament Log'!$N$4:$N$203,"<"&J37)+COUNTIF('Guest Log'!$K$4:$K$203,"<"&J37)+1)
J38: =IF(A38="","",A38+ROW()/10000000) | K38: =IF(J38="","",COUNTIF($J$3:$J$501,"<"&J38)+COUNTIF('Tournament Log'!$N$4:$N$203,"<"&J38)+COUNTIF('Guest Log'!$K$4:$K$203,"<"&J38)+1)
J39: =IF(A39="","",A39+ROW()/10000000) | K39: =IF(J39="","",COUNTIF($J$3:$J$501,"<"&J39)+COUNTIF('Tournament Log'!$N$4:$N$203,"<"&J39)+COUNTIF('Guest Log'!$K$4:$K$203,"<"&J39)+1)
J40: =IF(A40="","",A40+ROW()/10000000) | K40: =IF(J40="","",COUNTIF($J$3:$J$501,"<"&J40)+COUNTIF('Tournament Log'!$N$4:$N$203,"<"&J40)+COUNTIF('Guest Log'!$K$4:$K$203,"<"&J40)+1)
... J501: =IF(A501="","",A501+ROW()/10000000) | K501: =IF(J501="","",COUNTIF($J$3:$J$501,"<"&J501)+COUNTIF('Tournament Log'!$N$4:$N$203,"<"&J501)+COUNTIF('Guest Log'!$K$4:$K$203,"<"&J501)+1)

Sheet Tournament Log
A1: TOURNAMENT LOG — One row per player per tournament
A2: Date | B2: Tournament | C2: Player | D2: Rounds Played | E2: Wins | F2: Draws | G2: Losses | H2: Player VP Total | I2: Tournament SoS (0.00–1.00) | J2: Phantom Opp ELO (auto) | K2: Composite Score (auto) | L2: Faction Played | M2: Notes | N2: Sort Key (auto) | O2: Chrono Rank (auto)
A3: ℹ Phantom Opponent ELO = 800 + (SoS × 400). SoS 0.50 → ELO 1000 | SoS 0.75 → ELO 1100 | SoS 1.00 → ELO 1200. Composite Score = (Wins + 0.5×Draws) ÷ Rounds — treated as the ELO 'Actual' result against the phantom opponent.
A4: 46200 | B4: The Kelpie Cup #8 | C4: Andrew | D4: 3 | E4: 1 | F4: 0 | G4: 2 | H4: 242 | I4: 0.76 | J4: =IF(C4="","",IF(I4="","",ROUND(800+I4*400,0))) -> 1104 | K4: =IF(C4="","",IF(D4=0,"",ROUND((E4+0.5*F4)/D4,4))) -> 0.3333 | L4: Necrons | N4: =IF(A4="","",A4+0.0005+ROW()/10000000) -> 46200.001 | O4: =IF(N4="","",COUNTIF('Match Log'!$J$3:$J$501,"<"&N4)+COUNTIF($N$4:$N$203,"<"&N4)+COUNTIF('Guest Log'!$K$4:$K$203,"<"&N4)+1) -> 9
A5: 46198 | B5: Brewhammer GT9 | C5: John | D5: 5 | E5: 2 | F5: 0 | G5: 3 | H5: 378 | I5: 0.84 | J5: =IF(C5="","",IF(I5="","",ROUND(800+I5*400,0))) -> 1136 | K5: =IF(C5="","",IF(D5=0,"",ROUND((E5+0.5*F5)/D5,4))) -> 0.4 | L5: Blood Angels | N5: =IF(A5="","",A5+0.0005+ROW()/10000000) -> 46198.001 | O5: =IF(N5="","",COUNTIF('Match Log'!$J$3:$J$501,"<"&N5)+COUNTIF($N$4:$N$203,"<"&N5)+COUNTIF('Guest Log'!$K$4:$K$203,"<"&N5)+1) -> 7
A6: 46198 | B6: Brewhammer GT9 | C6: Gav | D6: 5 | E6: 3 | F6: 0 | G6: 2 | H6: 373 | I6: 0.75 | J6: =IF(C6="","",IF(I6="","",ROUND(800+I6*400,0))) -> 1100 | K6: =IF(C6="","",IF(D6=0,"",ROUND((E6+0.5*F6)/D6,4))) -> 0.6 | L6: Guard | N6: =IF(A6="","",A6+0.0005+ROW()/10000000) -> 46198.001 | O6: =IF(N6="","",COUNTIF('Match Log'!$J$3:$J$501,"<"&N6)+COUNTIF($N$4:$N$203,"<"&N6)+COUNTIF('Guest Log'!$K$4:$K$203,"<"&N6)+1) -> 8
J7: =IF(C7="","",IF(I7="","",ROUND(800+I7*400,0))) | K7: =IF(C7="","",IF(D7=0,"",ROUND((E7+0.5*F7)/D7,4))) | N7: =IF(A7="","",A7+0.0005+ROW()/10000000) | O7: =IF(N7="","",COUNTIF('Match Log'!$J$3:$J$501,"<"&N7)+COUNTIF($N$4:$N$203,"<"&N7)+COUNTIF('Guest Log'!$K$4:$K$203,"<"&N7)+1)
J8: =IF(C8="","",IF(I8="","",ROUND(800+I8*400,0))) | K8: =IF(C8="","",IF(D8=0,"",ROUND((E8+0.5*F8)/D8,4))) | N8: =IF(A8="","",A8+0.0005+ROW()/10000000) | O8: =IF(N8="","",COUNTIF('Match Log'!$J$3:$J$501,"<"&N8)+COUNTIF($N$4:$N$203,"<"&N8)+COUNTIF('Guest Log'!$K$4:$K$203,"<"&N8)+1)
J9: =IF(C9="","",IF(I9="","",ROUND(800+I9*400,0))) | K9: =IF(C9="","",IF(D9=0,"",ROUND((E9+0.5*F9)/D9,4))) | N9: =IF(A9="","",A9+0.0005+ROW()/10000000) | O9: =IF(N9="","",COUNTIF('Match Log'!$J$3:$J$501,"<"&N9)+COUNTIF($N$4:$N$203,"<"&N9)+COUNTIF('Guest Log'!$K$4:$K$203,"<"&N9)+1)
J10: =IF(C10="","",IF(I10="","",ROUND(800+I10*400,0))) | K10: =IF(C10="","",IF(D10=0,"",ROUND((E10+0.5*F10)/D10,4))) | N10: =IF(A10="","",A10+0.0005+ROW()/10000000) | O10: =IF(N10="","",COUNTIF('Match Log'!$J$3:$J$501,"<"&N10)+COUNTIF($N$4:$N$203,"<"&N10)+COUNTIF('Guest Log'!$K$4:$K$203,"<"&N10)+1)
J11: =IF(C11="","",IF(I11="","",ROUND(800+I11*400,0))) | K11: =IF(C11="","",IF(D11=0,"",ROUND((E11+0.5*F11)/D11,4))) | N11: =IF(A11="","",A11+0.0005+ROW()/10000000) | O11: =IF(N11="","",COUNTIF('Match Log'!$J$3:$J$501,"<"&N11)+COUNTIF($N$4:$N$203,"<"&N11)+COUNTIF('Guest Log'!$K$4:$K$203,"<"&N11)+1)
J12: =IF(C12="","",IF(I12="","",ROUND(800+I12*400,0))) | K12: =IF(C12="","",IF(D12=0,"",ROUND((E12+0.5*F12)/D12,4))) | N12: =IF(A12="","",A12+0.0005+ROW()/10000000) | O12: =IF(N12="","",COUNTIF('Match Log'!$J$3:$J$501,"<"&N12)+COUNTIF($N$4:$N$203,"<"&N12)+COUNTIF('Guest Log'!$K$4:$K$203,"<"&N12)+1)
J13: =IF(C13="","",IF(I13="","",ROUND(800+I13*400,0))) | K13: =IF(C13="","",IF(D13=0,"",ROUND((E13+0.5*F13)/D13,4))) | N13: =IF(A13="","",A13+0.0005+ROW()/10000000) | O13: =IF(N13="","",COUNTIF('Match Log'!$J$3:$J$501,"<"&N13)+COUNTIF($N$4:$N$203,"<"&N13)+COUNTIF('Guest Log'!$K$4:$K$203,"<"&N13)+1)
J14: =IF(C14="","",IF(I14="","",ROUND(800+I14*400,0))) | K14: =IF(C14="","",IF(D14=0,"",ROUND((E14+0.5*F14)/D14,4))) | N14: =IF(A14="","",A14+0.0005+ROW()/10000000) | O14: =IF(N14="","",COUNTIF('Match Log'!$J$3:$J$501,"<"&N14)+COUNTIF($N$4:$N$203,"<"&N14)+COUNTIF('Guest Log'!$K$4:$K$203,"<"&N14)+1)
J15: =IF(C15="","",IF(I15="","",ROUND(800+I15*400,0))) | K15: =IF(C15="","",IF(D15=0,"",ROUND((E15+0.5*F15)/D15,4))) | N15: =IF(A15="","",A15+0.0005+ROW()/10000000) | O15: =IF(N15="","",COUNTIF('Match Log'!$J$3:$J$501,"<"&N15)+COUNTIF($N$4:$N$203,"<"&N15)+COUNTIF('Guest Log'!$K$4:$K$203,"<"&N15)+1)
J16: =IF(C16="","",IF(I16="","",ROUND(800+I16*400,0))) | K16: =IF(C16="","",IF(D16=0,"",ROUND((E16+0.5*F16)/D16,4))) | N16: =IF(A16="","",A16+0.0005+ROW()/10000000) | O16: =IF(N16="","",COUNTIF('Match Log'!$J$3:$J$501,"<"&N16)+COUNTIF($N$4:$N$203,"<"&N16)+COUNTIF('Guest Log'!$K$4:$K$203,"<"&N16)+1)
J17: =IF(C17="","",IF(I17="","",ROUND(800+I17*400,0))) | K17: =IF(C17="","",IF(D17=0,"",ROUND((E17+0.5*F17)/D17,4))) | N17: =IF(A17="","",A17+0.0005+ROW()/10000000) | O17: =IF(N17="","",COUNTIF('Match Log'!$J$3:$J$501,"<"&N17)+COUNTIF($N$4:$N$203,"<"&N17)+COUNTIF('Guest Log'!$K$4:$K$203,"<"&N17)+1)
J18: =IF(C18="","",IF(I18="","",ROUND(800+I18*400,0))) | K18: =IF(C18="","",IF(D18=0,"",ROUND((E18+0.5*F18)/D18,4))) | N18: =IF(A18="","",A18+0.0005+ROW()/10000000) | O18: =IF(N18="","",COUNTIF('Match Log'!$J$3:$J$501,"<"&N18)+COUNTIF($N$4:$N$203,"<"&N18)+COUNTIF('Guest Log'!$K$4:$K$203,"<"&N18)+1)
... J203: =IF(C203="","",IF(I203="","",ROUND(800+I203*400,0))) | K203: =IF(C203="","",IF(D203=0,"",ROUND((E203+0.5*F203)/D203,4))) | N203: =IF(A203="","",A203+0.0005+ROW()/10000000) | O203: =IF(N203="","",COUNTIF('Match Log'!$J$3:$J$501,"<"&N203)+COUNTIF($N$4:$N$203,"<"&N203)+COUNTIF('Guest Log'!$K$4:$K$203,"<"&N203)+1)

Sheet Guest Log
A1: GUEST LOG — One row per game vs an unregistered / one-off opponent
A2: Date | B2: League Player | C2: Result (Player perspective) | D2: Player BP | E2: Opponent BP | F2: Player Faction | G2: Opponent Faction | H2: Guest Opponent Name | I2: Guest Opponent Est. ELO | J2: Notes | K2: Sort Key (auto) | L2: Chrono Rank (auto)
A3: ℹ Guest = a one-off opponent you do NOT want added to the League Table. Guest Opponent Est. ELO is a manual estimate of their strength (leave blank to default to 1000, a neutral 'unknown player' rating). This affects YOUR rating only — the guest's own rating is not tracked or carried between games, even if you reuse the same guest name.
A4: 08/13/2026 | B4: Allan | C4: Win | D4: 100 | E4: 56 | F4: Ad Mech | G4: Necrons | H4: Graeme | K4: =IF(A4="","",A4+0.0003+ROW()/10000000) -> #VALUE! | L4: =IF(K4="","",COUNTIF('Match Log'!$J$3:$J$501,"<"&K4)+COUNTIF('Tournament Log'!$N$4:$N$203,"<"&K4)+COUNTIF($K$4:$K$203,"<"&K4)+1) -> #VALUE!
K5: =IF(A5="","",A5+0.0003+ROW()/10000000) | L5: =IF(K5="","",COUNTIF('Match Log'!$J$3:$J$501,"<"&K5)+COUNTIF('Tournament Log'!$N$4:$N$203,"<"&K5)+COUNTIF($K$4:$K$203,"<"&K5)+1)
K6: =IF(A6="","",A6+0.0003+ROW()/10000000) | L6: =IF(K6="","",COUNTIF('Match Log'!$J$3:$J$501,"<"&K6)+COUNTIF('Tournament Log'!$N$4:$N$203,"<"&K6)+COUNTIF($K$4:$K$203,"<"&K6)+1)
K7: =IF(A7="","",A7+0.0003+ROW()/10000000) | L7: =IF(K7="","",COUNTIF('Match Log'!$J$3:$J$501,"<"&K7)+COUNTIF('Tournament Log'!$N$4:$N$203,"<"&K7)+COUNTIF($K$4:$K$203,"<"&K7)+1)
K8: =IF(A8="","",A8+0.0003+ROW()/10000000) | L8: =IF(K8="","",COUNTIF('Match Log'!$J$3:$J$501,"<"&K8)+COUNTIF('Tournament Log'!$N$4:$N$203,"<"&K8)+COUNTIF($K$4:$K$203,"<"&K8)+1)
K9: =IF(A9="","",A9+0.0003+ROW()/10000000) | L9: =IF(K9="","",COUNTIF('Match Log'!$J$3:$J$501,"<"&K9)+COUNTIF('Tournament Log'!$N$4:$N$203,"<"&K9)+COUNTIF($K$4:$K$203,"<"&K9)+1)
K10: =IF(A10="","",A10+0.0003+ROW()/10000000) | L10: =IF(K10="","",COUNTIF('Match Log'!$J$3:$J$501,"<"&K10)+COUNTIF('Tournament Log'!$N$4:$N$203,"<"&K10)+COUNTIF($K$4:$K$203,"<"&K10)+1)
K11: =IF(A11="","",A11+0.0003+ROW()/10000000) | L11: =IF(K11="","",COUNTIF('Match Log'!$J$3:$J$501,"<"&K11)+COUNTIF('Tournament Log'!$N$4:$N$203,"<"&K11)+COUNTIF($K$4:$K$203,"<"&K11)+1)
K12: =IF(A12="","",A12+0.0003+ROW()/10000000) | L12: =IF(K12="","",COUNTIF('Match Log'!$J$3:$J$501,"<"&K12)+COUNTIF('Tournament Log'!$N$4:$N$203,"<"&K12)+COUNTIF($K$4:$K$203,"<"&K12)+1)
K13: =IF(A13="","",A13+0.0003+ROW()/10000000) | L13: =IF(K13="","",COUNTIF('Match Log'!$J$3:$J$501,"<"&K13)+COUNTIF('Tournament Log'!$N$4:$N$203,"<"&K13)+COUNTIF($K$4:$K$203,"<"&K13)+1)
K14: =IF(A14="","",A14+0.0003+ROW()/10000000) | L14: =IF(K14="","",COUNTIF('Match Log'!$J$3:$J$501,"<"&K14)+COUNTIF('Tournament Log'!$N$4:$N$203,"<"&K14)+COUNTIF($K$4:$K$203,"<"&K14)+1)
K15: =IF(A15="","",A15+0.0003+ROW()/10000000) | L15: =IF(K15="","",COUNTIF('Match Log'!$J$3:$J$501,"<"&K15)+COUNTIF('Tournament Log'!$N$4:$N$203,"<"&K15)+COUNTIF($K$4:$K$203,"<"&K15)+1)
K16: =IF(A16="","",A16+0.0003+ROW()/10000000) | L16: =IF(K16="","",COUNTIF('Match Log'!$J$3:$J$501,"<"&K16)+COUNTIF('Tournament Log'!$N$4:$N$203,"<"&K16)+COUNTIF($K$4:$K$203,"<"&K16)+1)
... K203: =IF(A203="","",A203+0.0003+ROW()/10000000) | L203: =IF(K203="","",COUNTIF('Match Log'!$J$3:$J$501,"<"&K203)+COUNTIF('Tournament Log'!$N$4:$N$203,"<"&K203)+COUNTIF($K$4:$K$203,"<"&K203)+1)

Sheet ELO Engine
A1: Global Rank | B1: Date | C1: Event Type | D1: Match Log Row (auto) | E1: Tournament Log Row (auto) | F1: Player 1 | G1: Player 2 / Opponent | H1: ELO Before P1 | I1: Opponent ELO (Before P2 / Phantom) | J1: Expected P1 | K1: Actual P1 / Composite | L1: K-Factor | M1: ELO Change | N1: ELO After P1 | O1: ELO After P2 | P1: Tournament (if applicable) | Q1: Guest Log Row (auto)
A2: =1 -> 1 | B2: =IF(C2="","",IF(C2="Match",INDEX('Match Log'!$A:$A,D2),IF(C2="Tournament",INDEX('Tournament Log'!$A:$A,E2),INDEX('Guest Log'!$A:$A,Q2)))) -> 46190 | C2: =IF(D2<>"","Match",IF(E2<>"","Tournament",IF(Q2<>"","Guest",""))) -> Match | D2: =IFERROR(MATCH($A2,'Match Log'!$K$3:$K$501,0)+2,"") -> 3 | E2: =IFERROR(MATCH($A2,'Tournament Log'!$O$4:$O$203,0)+3,"") | F2: =IF(C2="","",IF(C2="Match",INDEX('Match Log'!$B:$B,D2),IF(C2="Tournament",INDEX('Tournament Log'!$C:$C,E2),INDEX('Guest Log'!$B:$B,Q2)))) -> Andrew | G2: =IF(C2="","",IF(C2="Match",INDEX('Match Log'!$C:$C,D2),IF(C2="Tournament",INDEX('Tournament Log'!$B:$B,E2)&" (Phantom)",INDEX('Guest Log'!$H:$H,Q2)&" (Guest)"))) -> Colin | H2: {=IF(C2="","",IFERROR(LOOKUP(2,1/(($F$1:F1=F2)+($G$1:G1=F2)),IF($F$1:F1=F2,$N$1:N1,$O$1:O1)),1000))} -> 1000 | I2: {=IF(C2="","",IF(C2="Tournament",INDEX('Tournament Log'!$J:$J,E2),IF(C2="Guest",IF(INDEX('Guest Log'!$I:$I,Q2)="",1000,INDEX('Guest Log'!$I:$I,Q2)),IFERROR(LOOKUP(2,1/(($F$1:F1=G2)+($G$1:G1=G2)),IF($F$1:F1=G2,$N$1:N1,$O$1:O1)),1000))))} -> 1000 | J2: =IF(C2="","",1/(1+10^((I2-H2)/400))) -> 0.5 | K2: =IF(C2="","",IF(C2="Match",IF(INDEX('Match Log'!$D:$D,D2)="Win",1,IF(INDEX('Match Log'!$D:$D,D2)="Draw",0.5,0)),IF(C2="Tournament",INDEX('Tournament Log'!$K:$K,E2),IF(INDEX('Guest Log'!$C:$C,Q2)="Win",1,IF(INDEX('Guest Log'!$C:$C,Q2)="Draw",0.5,0))))) -> 0 | L2: =IF(C2="","",IF(C2="Match",32,IF(C2="Tournament",MIN(32*INDEX('Tournament Log'!$D:$D,E2),96),32))) -> 32 | M2: =IF(C2="","",ROUND(L2*(K2-J2),0)) -> -16 | N2: =IF(C2="","",H2+M2) -> 984 | O2: =IF(C2="","",IF(C2="Match",I2-M2,"")) -> 1016 | P2: =IF(C2="Tournament",INDEX('Tournament Log'!$B:$B,E2),IF(C2="Guest","Guest: "&INDEX('Guest Log'!$H:$H,Q2),"")) | Q2: =IFERROR(MATCH($A2,'Guest Log'!$L$4:$L$203,0)+3,"")
A3: =2 -> 2 | B3: =IF(C3="","",IF(C3="Match",INDEX('Match Log'!$A:$A,D3),IF(C3="Tournament",INDEX('Tournament Log'!$A:$A,E3),INDEX('Guest Log'!$A:$A,Q3)))) -> 46193 | C3: =IF(D3<>"","Match",IF(E3<>"","Tournament",IF(Q3<>"","Guest",""))) -> Match | D3: =IFERROR(MATCH($A3,'Match Log'!$K$3:$K$501,0)+2,"") -> 4 | E3: =IFERROR(MATCH($A3,'Tournament Log'!$O$4:$O$203,0)+3,"") | F3: =IF(C3="","",IF(C3="Match",INDEX('Match Log'!$B:$B,D3),IF(C3="Tournament",INDEX('Tournament Log'!$C:$C,E3),INDEX('Guest Log'!$B:$B,Q3)))) -> Andrew | G3: =IF(C3="","",IF(C3="Match",INDEX('Match Log'!$C:$C,D3),IF(C3="Tournament",INDEX('Tournament Log'!$B:$B,E3)&" (Phantom)",INDEX('Guest Log'!$H:$H,Q3)&" (Guest)"))) -> Colin | H3: {=IF(C3="","",IFERROR(LOOKUP(2,1/(($F$1:F2=F3)+($G$1:G2=F3)),IF($F$1:F2=F3,$N$1:N2,$O$1:O2)),1000))} -> 984 | I3: {=IF(C3="","",IF(C3="Tournament",INDEX('Tournament Log'!$J:$J,E3),IF(C3="Guest",IF(INDEX('Guest Log'!$I:$I,Q3)="",1000,INDEX('Guest Log'!$I:$I,Q3)),IFERROR(LOOKUP(2,1/(($F$1:F2=G3)+($G$1:G2=G3)),IF($F$1:F2=G3,$N$1:N2,$O$1:O2)),1000))))} -> 1016 | J3: =IF(C3="","",1/(1+10^((I3-H3)/400))) -> 0.45407808 | K3: =IF(C3="","",IF(C3="Match",IF(INDEX('Match Log'!$D:$D,D3)="Win",1,IF(INDEX('Match Log'!$D:$D,D3)="Draw",0.5,0)),IF(C3="Tournament",INDEX('Tournament Log'!$K:$K,E3),IF(INDEX('Guest Log'!$C:$C,Q3)="Win",1,IF(INDEX('Guest Log'!$C:$C,Q3)="Draw",0.5,0))))) -> 1 | L3: =IF(C3="","",IF(C3="Match",32,IF(C3="Tournament",MIN(32*INDEX('Tournament Log'!$D:$D,E3),96),32))) -> 32 | M3: =IF(C3="","",ROUND(L3*(K3-J3),0)) -> 17 | N3: =IF(C3="","",H3+M3) -> 1001 | O3: =IF(C3="","",IF(C3="Match",I3-M3,"")) -> 999 | P3: =IF(C3="Tournament",INDEX('Tournament Log'!$B:$B,E3),IF(C3="Guest","Guest: "&INDEX('Guest Log'!$H:$H,Q3),"")) | Q3: =IFERROR(MATCH($A3,'Guest Log'!$L$4:$L$203,0)+3,"")
A4: =3 -> 3 | B4: =IF(C4="","",IF(C4="Match",INDEX('Match Log'!$A:$A,D4),IF(C4="Tournament",INDEX('Tournament Log'!$A:$A,E4),INDEX('Guest Log'!$A:$A,Q4)))) -> 46193 | C4: =IF(D4<>"","Match",IF(E4<>"","Tournament",IF(Q4<>"","Guest",""))) -> Match | D4: =IFERROR(MATCH($A4,'Match Log'!$K$3:$K$501,0)+2,"") -> 5 | E4: =IFERROR(MATCH($A4,'Tournament Log'!$O$4:$O$203,0)+3,"") | F4: =IF(C4="","",IF(C4="Match",INDEX('Match Log'!$B:$B,D4),IF(C4="Tournament",INDEX('Tournament Log'!$C:$C,E4),INDEX('Guest Log'!$B:$B,Q4)))) -> Andrew | G4: =IF(C4="","",IF(C4="Match",INDEX('Match Log'!$C:$C,D4),IF(C4="Tournament",INDEX('Tournament Log'!$B:$B,E4)&" (Phantom)",INDEX('Guest Log'!$H:$H,Q4)&" (Guest)"))) -> Miles | H4: {=IF(C4="","",IFERROR(LOOKUP(2,1/(($F$1:F3=F4)+($G$1:G3=F4)),IF($F$1:F3=F4,$N$1:N3,$O$1:O3)),1000))} -> 1001 | I4: {=IF(C4="","",IF(C4="Tournament",INDEX('Tournament Log'!$J:$J,E4),IF(C4="Guest",IF(INDEX('Guest Log'!$I:$I,Q4)="",1000,INDEX('Guest Log'!$I:$I,Q4)),IFERROR(LOOKUP(2,1/(($F$1:F3=G4)+($G$1:G3=G4)),IF($F$1:F3=G4,$N$1:N3,$O$1:O3)),1000))))} -> 1000 | J4: =IF(C4="","",1/(1+10^((I4-H4)/400))) -> 0.50143911 | K4: =IF(C4="","",IF(C4="Match",IF(INDEX('Match Log'!$D:$D,D4)="Win",1,IF(INDEX('Match Log'!$D:$D,D4)="Draw",0.5,0)),IF(C4="Tournament",INDEX('Tournament Log'!$K:$K,E4),IF(INDEX('Guest Log'!$C:$C,Q4)="Win",1,IF(INDEX('Guest Log'!$C:$C,Q4)="Draw",0.5,0))))) -> 0 | L4: =IF(C4="","",IF(C4="Match",32,IF(C4="Tournament",MIN(32*INDEX('Tournament Log'!$D:$D,E4),96),32))) -> 32 | M4: =IF(C4="","",ROUND(L4*(K4-J4),0)) -> -16 | N4: =IF(C4="","",H4+M4) -> 985 | O4: =IF(C4="","",IF(C4="Match",I4-M4,"")) -> 1016 | P4: =IF(C4="Tournament",INDEX('Tournament Log'!$B:$B,E4),IF(C4="Guest","Guest: "&INDEX('Guest Log'!$H:$H,Q4),"")) | Q4: =IFERROR(MATCH($A4,'Guest Log'!$L$4:$L$203,0)+3,"")
A5: =4 -> 4 | B5: =IF(C5="","",IF(C5="Match",INDEX('Match Log'!$A:$A,D5),IF(C5="Tournament",INDEX('Tournament Log'!$A:$A,E5),INDEX('Guest Log'!$A:$A,Q5)))) -> 46193 | C5: =IF(D5<>"","Match",IF(E5<>"","Tournament",IF(Q5<>"","Guest",""))) -> Match | D5: =IFERROR(MATCH($A5,'Match Log'!$K$3:$K$501,0)+2,"") -> 6 | E5: =IFERROR(MATCH($A5,'Tournament Log'!$O$4:$O$203,0)+3,"") | F5: =IF(C5="","",IF(C5="Match",INDEX('Match Log'!$B:$B,D5),IF(C5="Tournament",INDEX('Tournament Log'!$C:$C,E5),INDEX('Guest Log'!$B:$B,Q5)))) -> John | G5: =IF(C5="","",IF(C5="Match",INDEX('Match Log'!$C:$C,D5),IF(C5="Tournament",INDEX('Tournament Log'!$B:$B,E5)&" (Phantom)",INDEX('Guest Log'!$H:$H,Q5)&" (Guest)"))) -> Colin | H5: {=IF(C5="","",IFERROR(LOOKUP(2,1/(($F$1:F4=F5)+($G$1:G4=F5)),IF($F$1:F4=F5,$N$1:N4,$O$1:O4)),1000))} -> 1000 | I5: {=IF(C5="","",IF(C5="Tournament",INDEX('Tournament Log'!$J:$J,E5),IF(C5="Guest",IF(INDEX('Guest Log'!$I:$I,Q5)="",1000,INDEX('Guest Log'!$I:$I,Q5)),IFERROR(LOOKUP(2,1/(($F$1:F4=G5)+($G$1:G4=G5)),IF($F$1:F4=G5,$N$1:N4,$O$1:O4)),1000))))} -> 999 | J5: =IF(C5="","",1/(1+10^((I5-H5)/400))) -> 0.50143911 | K5: =IF(C5="","",IF(C5="Match",IF(INDEX('Match Log'!$D:$D,D5)="Win",1,IF(INDEX('Match Log'!$D:$D,D5)="Draw",0.5,0)),IF(C5="Tournament",INDEX('Tournament Log'!$K:$K,E5),IF(INDEX('Guest Log'!$C:$C,Q5)="Win",1,IF(INDEX('Guest Log'!$C:$C,Q5)="Draw",0.5,0))))) -> 1 | L5: =IF(C5="","",IF(C5="Match",32,IF(C5="Tournament",MIN(32*INDEX('Tournament Log'!$D:$D,E5),96),32))) -> 32 | M5: =IF(C5="","",ROUND(L5*(K5-J5),0)) -> 16 | N5: =IF(C5="","",H5+M5) -> 1016 | O5: =IF(C5="","",IF(C5="Match",I5-M5,"")) -> 983 | P5: =IF(C5="Tournament",INDEX('Tournament Log'!$B:$B,E5),IF(C5="Guest","Guest: "&INDEX('Guest Log'!$H:$H,Q5),"")) | Q5: =IFERROR(MATCH($A5,'Guest Log'!$L$4:$L$203,0)+3,"")
A6: =5 -> 5 | B6: =IF(C6="","",IF(C6="Match",INDEX('Match Log'!$A:$A,D6),IF(C6="Tournament",INDEX('Tournament Log'!$A:$A,E6),INDEX('Guest Log'!$A:$A,Q6)))) -> 46195 | C6: =IF(D6<>"","Match",IF(E6<>"","Tournament",IF(Q6<>"","Guest",""))) -> Match | D6: =IFERROR(MATCH($A6,'Match Log'!$K$3:$K$501,0)+2,"") -> 7 | E6: =IFERROR(MATCH($A6,'Tournament Log'!$O$4:$O$203,0)+3,"") | F6: =IF(C6="","",IF(C6="Match",INDEX('Match Log'!$B:$B,D6),IF(C6="Tournament",INDEX('Tournament Log'!$C:$C,E6),INDEX('Guest Log'!$B:$B,Q6)))) -> Brett | G6: =IF(C6="","",IF(C6="Match",INDEX('Match Log'!$C:$C,D6),IF(C6="Tournament",INDEX('Tournament Log'!$B:$B,E6)&" (Phantom)",INDEX('Guest Log'!$H:$H,Q6)&" (Guest)"))) -> Colin | H6: {=IF(C6="","",IFERROR(LOOKUP(2,1/(($F$1:F5=F6)+($G$1:G5=F6)),IF($F$1:F5=F6,$N$1:N5,$O$1:O5)),1000))} -> 1000 | I6: {=IF(C6="","",IF(C6="Tournament",INDEX('Tournament Log'!$J:$J,E6),IF(C6="Guest",IF(INDEX('Guest Log'!$I:$I,Q6)="",1000,INDEX('Guest Log'!$I:$I,Q6)),IFERROR(LOOKUP(2,1/(($F$1:F5=G6)+($G$1:G5=G6)),IF($F$1:F5=G6,$N$1:N5,$O$1:O5)),1000))))} -> 983 | J6: =IF(C6="","",1/(1+10^((I6-H6)/400))) -> 0.52444546 | K6: =IF(C6="","",IF(C6="Match",IF(INDEX('Match Log'!$D:$D,D6)="Win",1,IF(INDEX('Match Log'!$D:$D,D6)="Draw",0.5,0)),IF(C6="Tournament",INDEX('Tournament Log'!$K:$K,E6),IF(INDEX('Guest Log'!$C:$C,Q6)="Win",1,IF(INDEX('Guest Log'!$C:$C,Q6)="Draw",0.5,0))))) -> 0 | L6: =IF(C6="","",IF(C6="Match",32,IF(C6="Tournament",MIN(32*INDEX('Tournament Log'!$D:$D,E6),96),32))) -> 32 | M6: =IF(C6="","",ROUND(L6*(K6-J6),0)) -> -17 | N6: =IF(C6="","",H6+M6) -> 983 | O6: =IF(C6="","",IF(C6="Match",I6-M6,"")) -> 1000 | P6: =IF(C6="Tournament",INDEX('Tournament Log'!$B:$B,E6),IF(C6="Guest","Guest: "&INDEX('Guest Log'!$H:$H,Q6),"")) | Q6: =IFERROR(MATCH($A6,'Guest Log'!$L$4:$L$203,0)+3,"")
A7: =6 -> 6 | B7: =IF(C7="","",IF(C7="Match",INDEX('Match Log'!$A:$A,D7),IF(C7="Tournament",INDEX('Tournament Log'!$A:$A,E7),INDEX('Guest Log'!$A:$A,Q7)))) -> 46196 | C7: =IF(D7<>"","Match",IF(E7<>"","Tournament",IF(Q7<>"","Guest",""))) -> Match | D7: =IFERROR(MATCH($A7,'Match Log'!$K$3:$K$501,0)+2,"") -> 8 | E7: =IFERROR(MATCH($A7,'Tournament Log'!$O$4:$O$203,0)+3,"") | F7: =IF(C7="","",IF(C7="Match",INDEX('Match Log'!$B:$B,D7),IF(C7="Tournament",INDEX('Tournament Log'!$C:$C,E7),INDEX('Guest Log'!$B:$B,Q7)))) -> Andrew | G7: =IF(C7="","",IF(C7="Match",INDEX('Match Log'!$C:$C,D7),IF(C7="Tournament",INDEX('Tournament Log'!$B:$B,E7)&" (Phantom)",INDEX('Guest Log'!$H:$H,Q7)&" (Guest)"))) -> Colin | H7: {=IF(C7="","",IFERROR(LOOKUP(2,1/(($F$1:F6=F7)+($G$1:G6=F7)),IF($F$1:F6=F7,$N$1:N6,$O$1:O6)),1000))} -> 985 | I7: {=IF(C7="","",IF(C7="Tournament",INDEX('Tournament Log'!$J:$J,E7),IF(C7="Guest",IF(INDEX('Guest Log'!$I:$I,Q7)="",1000,INDEX('Guest Log'!$I:$I,Q7)),IFERROR(LOOKUP(2,1/(($F$1:F6=G7)+($G$1:G6=G7)),IF($F$1:F6=G7,$N$1:N6,$O$1:O6)),1000))))} -> 1000 | J7: =IF(C7="","",1/(1+10^((I7-H7)/400))) -> 0.47842667 | K7: =IF(C7="","",IF(C7="Match",IF(INDEX('Match Log'!$D:$D,D7)="Win",1,IF(INDEX('Match Log'!$D:$D,D7)="Draw",0.5,0)),IF(C7="Tournament",INDEX('Tournament Log'!$K:$K,E7),IF(INDEX('Guest Log'!$C:$C,Q7)="Win",1,IF(INDEX('Guest Log'!$C:$C,Q7)="Draw",0.5,0))))) -> 0 | L7: =IF(C7="","",IF(C7="Match",32,IF(C7="Tournament",MIN(32*INDEX('Tournament Log'!$D:$D,E7),96),32))) -> 32 | M7: =IF(C7="","",ROUND(L7*(K7-J7),0)) -> -15 | N7: =IF(C7="","",H7+M7) -> 970 | O7: =IF(C7="","",IF(C7="Match",I7-M7,"")) -> 1015 | P7: =IF(C7="Tournament",INDEX('Tournament Log'!$B:$B,E7),IF(C7="Guest","Guest: "&INDEX('Guest Log'!$H:$H,Q7),"")) | Q7: =IFERROR(MATCH($A7,'Guest Log'!$L$4:$L$203,0)+3,"")
A8: =7 -> 7 | B8: =IF(C8="","",IF(C8="Match",INDEX('Match Log'!$A:$A,D8),IF(C8="Tournament",INDEX('Tournament Log'!$A:$A,E8),INDEX('Guest Log'!$A:$A,Q8)))) -> 46198 | C8: =IF(D8<>"","Match",IF(E8<>"","Tournament",IF(Q8<>"","Guest",""))) -> Tournament | D8: =IFERROR(MATCH($A8,'Match Log'!$K$3:$K$501,0)+2,"") | E8: =IFERROR(MATCH($A8,'Tournament Log'!$O$4:$O$203,0)+3,"") -> 5 | F8: =IF(C8="","",IF(C8="Match",INDEX('Match Log'!$B:$B,D8),IF(C8="Tournament",INDEX('Tournament Log'!$C:$C,E8),INDEX('Guest Log'!$B:$B,Q8)))) -> John | G8: =IF(C8="","",IF(C8="Match",INDEX('Match Log'!$C:$C,D8),IF(C8="Tournament",INDEX('Tournament Log'!$B:$B,E8)&" (Phantom)",INDEX('Guest Log'!$H:$H,Q8)&" (Guest)"))) -> Brewhammer GT9 (Phantom) | H8: {=IF(C8="","",IFERROR(LOOKUP(2,1/(($F$1:F7=F8)+($G$1:G7=F8)),IF($F$1:F7=F8,$N$1:N7,$O$1:O7)),1000))} -> 1016 | I8: {=IF(C8="","",IF(C8="Tournament",INDEX('Tournament Log'!$J:$J,E8),IF(C8="Guest",IF(INDEX('Guest Log'!$I:$I,Q8)="",1000,INDEX('Guest Log'!$I:$I,Q8)),IFERROR(LOOKUP(2,1/(($F$1:F7=G8)+($G$1:G7=G8)),IF($F$1:F7=G8,$N$1:N7,$O$1:O7)),1000))))} -> 1136 | J8: =IF(C8="","",1/(1+10^((I8-H8)/400))) -> 0.33386058 | K8: =IF(C8="","",IF(C8="Match",IF(INDEX('Match Log'!$D:$D,D8)="Win",1,IF(INDEX('Match Log'!$D:$D,D8)="Draw",0.5,0)),IF(C8="Tournament",INDEX('Tournament Log'!$K:$K,E8),IF(INDEX('Guest Log'!$C:$C,Q8)="Win",1,IF(INDEX('Guest Log'!$C:$C,Q8)="Draw",0.5,0))))) -> 0.4 | L8: =IF(C8="","",IF(C8="Match",32,IF(C8="Tournament",MIN(32*INDEX('Tournament Log'!$D:$D,E8),96),32))) -> 96 | M8: =IF(C8="","",ROUND(L8*(K8-J8),0)) -> 6 | N8: =IF(C8="","",H8+M8) -> 1022 | O8: =IF(C8="","",IF(C8="Match",I8-M8,"")) | P8: =IF(C8="Tournament",INDEX('Tournament Log'!$B:$B,E8),IF(C8="Guest","Guest: "&INDEX('Guest Log'!$H:$H,Q8),"")) -> Brewhammer GT9 | Q8: =IFERROR(MATCH($A8,'Guest Log'!$L$4:$L$203,0)+3,"")
A9: =8 -> 8 | B9: =IF(C9="","",IF(C9="Match",INDEX('Match Log'!$A:$A,D9),IF(C9="Tournament",INDEX('Tournament Log'!$A:$A,E9),INDEX('Guest Log'!$A:$A,Q9)))) -> 46198 | C9: =IF(D9<>"","Match",IF(E9<>"","Tournament",IF(Q9<>"","Guest",""))) -> Tournament | D9: =IFERROR(MATCH($A9,'Match Log'!$K$3:$K$501,0)+2,"") | E9: =IFERROR(MATCH($A9,'Tournament Log'!$O$4:$O$203,0)+3,"") -> 6 | F9: =IF(C9="","",IF(C9="Match",INDEX('Match Log'!$B:$B,D9),IF(C9="Tournament",INDEX('Tournament Log'!$C:$C,E9),INDEX('Guest Log'!$B:$B,Q9)))) -> Gav | G9: =IF(C9="","",IF(C9="Match",INDEX('Match Log'!$C:$C,D9),IF(C9="Tournament",INDEX('Tournament Log'!$B:$B,E9)&" (Phantom)",INDEX('Guest Log'!$H:$H,Q9)&" (Guest)"))) -> Brewhammer GT9 (Phantom) | H9: {=IF(C9="","",IFERROR(LOOKUP(2,1/(($F$1:F8=F9)+($G$1:G8=F9)),IF($F$1:F8=F9,$N$1:N8,$O$1:O8)),1000))} -> 1000 | I9: {=IF(C9="","",IF(C9="Tournament",INDEX('Tournament Log'!$J:$J,E9),IF(C9="Guest",IF(INDEX('Guest Log'!$I:$I,Q9)="",1000,INDEX('Guest Log'!$I:$I,Q9)),IFERROR(LOOKUP(2,1/(($F$1:F8=G9)+($G$1:G8=G9)),IF($F$1:F8=G9,$N$1:N8,$O$1:O8)),1000))))} -> 1100 | J9: =IF(C9="","",1/(1+10^((I9-H9)/400))) -> 0.359935 | K9: =IF(C9="","",IF(C9="Match",IF(INDEX('Match Log'!$D:$D,D9)="Win",1,IF(INDEX('Match Log'!$D:$D,D9)="Draw",0.5,0)),IF(C9="Tournament",INDEX('Tournament Log'!$K:$K,E9),IF(INDEX('Guest Log'!$C:$C,Q9)="Win",1,IF(INDEX('Guest Log'!$C:$C,Q9)="Draw",0.5,0))))) -> 0.6 | L9: =IF(C9="","",IF(C9="Match",32,IF(C9="Tournament",MIN(32*INDEX('Tournament Log'!$D:$D,E9),96),32))) -> 96 | M9: =IF(C9="","",ROUND(L9*(K9-J9),0)) -> 23 | N9: =IF(C9="","",H9+M9) -> 1023 | O9: =IF(C9="","",IF(C9="Match",I9-M9,"")) | P9: =IF(C9="Tournament",INDEX('Tournament Log'!$B:$B,E9),IF(C9="Guest","Guest: "&INDEX('Guest Log'!$H:$H,Q9),"")) -> Brewhammer GT9 | Q9: =IFERROR(MATCH($A9,'Guest Log'!$L$4:$L$203,0)+3,"")
A10: =9 -> 9 | B10: =IF(C10="","",IF(C10="Match",INDEX('Match Log'!$A:$A,D10),IF(C10="Tournament",INDEX('Tournament Log'!$A:$A,E10),INDEX('Guest Log'!$A:$A,Q10)))) -> 46200 | C10: =IF(D10<>"","Match",IF(E10<>"","Tournament",IF(Q10<>"","Guest",""))) -> Tournament | D10: =IFERROR(MATCH($A10,'Match Log'!$K$3:$K$501,0)+2,"") | E10: =IFERROR(MATCH($A10,'Tournament Log'!$O$4:$O$203,0)+3,"") -> 4 | F10: =IF(C10="","",IF(C10="Match",INDEX('Match Log'!$B:$B,D10),IF(C10="Tournament",INDEX('Tournament Log'!$C:$C,E10),INDEX('Guest Log'!$B:$B,Q10)))) -> Andrew | G10: =IF(C10="","",IF(C10="Match",INDEX('Match Log'!$C:$C,D10),IF(C10="Tournament",INDEX('Tournament Log'!$B:$B,E10)&" (Phantom)",INDEX('Guest Log'!$H:$H,Q10)&" (Guest)"))) -> The Kelpie Cup #8 (Phantom) | H10: {=IF(C10="","",IFERROR(LOOKUP(2,1/(($F$1:F9=F10)+($G$1:G9=F10)),IF($F$1:F9=F10,$N$1:N9,$O$1:O9)),1000))} -> 970 | I10: {=IF(C10="","",IF(C10="Tournament",INDEX('Tournament Log'!$J:$J,E10),IF(C10="Guest",IF(INDEX('Guest Log'!$I:$I,Q10)="",1000,INDEX('Guest Log'!$I:$I,Q10)),IFERROR(LOOKUP(2,1/(($F$1:F9=G10)+($G$1:G9=G10)),IF($F$1:F9=G10,$N$1:N9,$O$1:O9)),1000))))} -> 1104 | J10: =IF(C10="","",1/(1+10^((I10-H10)/400))) -> 0.31618369 | K10: =IF(C10="","",IF(C10="Match",IF(INDEX('Match Log'!$D:$D,D10)="Win",1,IF(INDEX('Match Log'!$D:$D,D10)="Draw",0.5,0)),IF(C10="Tournament",INDEX('Tournament Log'!$K:$K,E10),IF(INDEX('Guest Log'!$C:$C,Q10)="Win",1,IF(INDEX('Guest Log'!$C:$C,Q10)="Draw",0.5,0))))) -> 0.3333 | L10: =IF(C10="","",IF(C10="Match",32,IF(C10="Tournament",MIN(32*INDEX('Tournament Log'!$D:$D,E10),96),32))) -> 96 | M10: =IF(C10="","",ROUND(L10*(K10-J10),0)) -> 2 | N10: =IF(C10="","",H10+M10) -> 972 | O10: =IF(C10="","",IF(C10="Match",I10-M10,"")) | P10: =IF(C10="Tournament",INDEX('Tournament Log'!$B:$B,E10),IF(C10="Guest","Guest: "&INDEX('Guest Log'!$H:$H,Q10),"")) -> The Kelpie Cup #8 | Q10: =IFERROR(MATCH($A10,'Guest Log'!$L$4:$L$203,0)+3,"")
A11: =10 -> 10 | B11: =IF(C11="","",IF(C11="Match",INDEX('Match Log'!$A:$A,D11),IF(C11="Tournament",INDEX('Tournament Log'!$A:$A,E11),INDEX('Guest Log'!$A:$A,Q11)))) -> 46202 | C11: =IF(D11<>"","Match",IF(E11<>"","Tournament",IF(Q11<>"","Guest",""))) -> Match | D11: =IFERROR(MATCH($A11,'Match Log'!$K$3:$K$501,0)+2,"") -> 9 | E11: =IFERROR(MATCH($A11,'Tournament Log'!$O$4:$O$203,0)+3,"") | F11: =IF(C11="","",IF(C11="Match",INDEX('Match Log'!$B:$B,D11),IF(C11="Tournament",INDEX('Tournament Log'!$C:$C,E11),INDEX('Guest Log'!$B:$B,Q11)))) -> Gav | G11: =IF(C11="","",IF(C11="Match",INDEX('Match Log'!$C:$C,D11),IF(C11="Tournament",INDEX('Tournament Log'!$B:$B,E11)&" (Phantom)",INDEX('Guest Log'!$H:$H,Q11)&" (Guest)"))) -> Brett | H11: {=IF(C11="","",IFERROR(LOOKUP(2,1/(($F$1:F10=F11)+($G$1:G10=F11)),IF($F$1:F10=F11,$N$1:N10,$O$1:O10)),1000))} -> 1023 | I11: {=IF(C11="","",IF(C11="Tournament",INDEX('Tournament Log'!$J:$J,E11),IF(C11="Guest",IF(INDEX('Guest Log'!$I:$I,Q11)="",1000,INDEX('Guest Log'!$I:$I,Q11)),IFERROR(LOOKUP(2,1/(($F$1:F10=G11)+($G$1:G10=G11)),IF($F$1:F10=G11,$N$1:N10,$O$1:O10)),1000))))} -> 983 | J11: =IF(C11="","",1/(1+10^((I11-H11)/400))) -> 0.55731163 | K11: =IF(C11="","",IF(C11="Match",IF(INDEX('Match Log'!$D:$D,D11)="Win",1,IF(INDEX('Match Log'!$D:$D,D11)="Draw",0.5,0)),IF(C11="Tournament",INDEX('Tournament Log'!$K:$K,E11),IF(INDEX('Guest Log'!$C:$C,Q11)="Win",1,IF(INDEX('Guest Log'!$C:$C,Q11)="Draw",0.5,0))))) -> 1 | L11: =IF(C11="","",IF(C11="Match",32,IF(C11="Tournament",MIN(32*INDEX('Tournament Log'!$D:$D,E11),96),32))) -> 32 | M11: =IF(C11="","",ROUND(L11*(K11-J11),0)) -> 14 | N11: =IF(C11="","",H11+M11) -> 1037 | O11: =IF(C11="","",IF(C11="Match",I11-M11,"")) -> 969 | P11: =IF(C11="Tournament",INDEX('Tournament Log'!$B:$B,E11),IF(C11="Guest","Guest: "&INDEX('Guest Log'!$H:$H,Q11),"")) | Q11: =IFERROR(MATCH($A11,'Guest Log'!$L$4:$L$203,0)+3,"")
A12: =11 -> 11 | B12: =IF(C12="","",IF(C12="Match",INDEX('Match Log'!$A:$A,D12),IF(C12="Tournament",INDEX('Tournament Log'!$A:$A,E12),INDEX('Guest Log'!$A:$A,Q12)))) -> 46203 | C12: =IF(D12<>"","Match",IF(E12<>"","Tournament",IF(Q12<>"","Guest",""))) -> Match | D12: =IFERROR(MATCH($A12,'Match Log'!$K$3:$K$501,0)+2,"") -> 10 | E12: =IFERROR(MATCH($A12,'Tournament Log'!$O$4:$O$203,0)+3,"") | F12: =IF(C12="","",IF(C12="Match",INDEX('Match Log'!$B:$B,D12),IF(C12="Tournament",INDEX('Tournament Log'!$C:$C,E12),INDEX('Guest Log'!$B:$B,Q12)))) -> Andrew | G12: =IF(C12="","",IF(C12="Match",INDEX('Match Log'!$C:$C,D12),IF(C12="Tournament",INDEX('Tournament Log'!$B:$B,E12)&" (Phantom)",INDEX('Guest Log'!$H:$H,Q12)&" (Guest)"))) -> Colin | H12: {=IF(C12="","",IFERROR(LOOKUP(2,1/(($F$1:F11=F12)+($G$1:G11=F12)),IF($F$1:F11=F12,$N$1:N11,$O$1:O11)),1000))} -> 972 | I12: {=IF(C12="","",IF(C12="Tournament",INDEX('Tournament Log'!$J:$J,E12),IF(C12="Guest",IF(INDEX('Guest Log'!$I:$I,Q12)="",1000,INDEX('Guest Log'!$I:$I,Q12)),IFERROR(LOOKUP(2,1/(($F$1:F11=G12)+($G$1:G11=G12)),IF($F$1:F11=G12,$N$1:N11,$O$1:O11)),1000))))} -> 1015 | J12: =IF(C12="","",1/(1+10^((I12-H12)/400))) -> 0.43843206 | K12: =IF(C12="","",IF(C12="Match",IF(INDEX('Match Log'!$D:$D,D12)="Win",1,IF(INDEX('Match Log'!$D:$D,D12)="Draw",0.5,0)),IF(C12="Tournament",INDEX('Tournament Log'!$K:$K,E12),IF(INDEX('Guest Log'!$C:$C,Q12)="Win",1,IF(INDEX('Guest Log'!$C:$C,Q12)="Draw",0.5,0))))) -> 0 | L12: =IF(C12="","",IF(C12="Match",32,IF(C12="Tournament",MIN(32*INDEX('Tournament Log'!$D:$D,E12),96),32))) -> 32 | M12: =IF(C12="","",ROUND(L12*(K12-J12),0)) -> -14 | N12: =IF(C12="","",H12+M12) -> 958 | O12: =IF(C12="","",IF(C12="Match",I12-M12,"")) -> 1029 | P12: =IF(C12="Tournament",INDEX('Tournament Log'!$B:$B,E12),IF(C12="Guest","Guest: "&INDEX('Guest Log'!$H:$H,Q12),"")) | Q12: =IFERROR(MATCH($A12,'Guest Log'!$L$4:$L$203,0)+3,"")
A13: =12 -> 12 | B13: =IF(C13="","",IF(C13="Match",INDEX('Match Log'!$A:$A,D13),IF(C13="Tournament",INDEX('Tournament Log'!$A:$A,E13),INDEX('Guest Log'!$A:$A,Q13)))) -> 46204 | C13: =IF(D13<>"","Match",IF(E13<>"","Tournament",IF(Q13<>"","Guest",""))) -> Match | D13: =IFERROR(MATCH($A13,'Match Log'!$K$3:$K$501,0)+2,"") -> 11 | E13: =IFERROR(MATCH($A13,'Tournament Log'!$O$4:$O$203,0)+3,"") | F13: =IF(C13="","",IF(C13="Match",INDEX('Match Log'!$B:$B,D13),IF(C13="Tournament",INDEX('Tournament Log'!$C:$C,E13),INDEX('Guest Log'!$B:$B,Q13)))) -> John | G13: =IF(C13="","",IF(C13="Match",INDEX('Match Log'!$C:$C,D13),IF(C13="Tournament",INDEX('Tournament Log'!$B:$B,E13)&" (Phantom)",INDEX('Guest Log'!$H:$H,Q13)&" (Guest)"))) -> Colin | H13: {=IF(C13="","",IFERROR(LOOKUP(2,1/(($F$1:F12=F13)+($G$1:G12=F13)),IF($F$1:F12=F13,$N$1:N12,$O$1:O12)),1000))} -> 1022 | I13: {=IF(C13="","",IF(C13="Tournament",INDEX('Tournament Log'!$J:$J,E13),IF(C13="Guest",IF(INDEX('Guest Log'!$I:$I,Q13)="",1000,INDEX('Guest Log'!$I:$I,Q13)),IFERROR(LOOKUP(2,1/(($F$1:F12=G13)+($G$1:G12=G13)),IF($F$1:F12=G13,$N$1:N12,$O$1:O12)),1000))))} -> 1029 | J13: =IF(C13="","",1/(1+10^((I13-H13)/400))) -> 0.48992755 | K13: =IF(C13="","",IF(C13="Match",IF(INDEX('Match Log'!$D:$D,D13)="Win",1,IF(INDEX('Match Log'!$D:$D,D13)="Draw",0.5,0)),IF(C13="Tournament",INDEX('Tournament Log'!$K:$K,E13),IF(INDEX('Guest Log'!$C:$C,Q13)="Win",1,IF(INDEX('Guest Log'!$C:$C,Q13)="Draw",0.5,0))))) -> 1 | L13: =IF(C13="","",IF(C13="Match",32,IF(C13="Tournament",MIN(32*INDEX('Tournament Log'!$D:$D,E13),96),32))) -> 32 | M13: =IF(C13="","",ROUND(L13*(K13-J13),0)) -> 16 | N13: =IF(C13="","",H13+M13) -> 1038 | O13: =IF(C13="","",IF(C13="Match",I13-M13,"")) -> 1013 | P13: =IF(C13="Tournament",INDEX('Tournament Log'!$B:$B,E13),IF(C13="Guest","Guest: "&INDEX('Guest Log'!$H:$H,Q13),"")) | Q13: =IFERROR(MATCH($A13,'Guest Log'!$L$4:$L$203,0)+3,"")
A14: =13 -> 13 | B14: =IF(C14="","",IF(C14="Match",INDEX('Match Log'!$A:$A,D14),IF(C14="Tournament",INDEX('Tournament Log'!$A:$A,E14),INDEX('Guest Log'!$A:$A,Q14)))) -> 46205 | C14: =IF(D14<>"","Match",IF(E14<>"","Tournament",IF(Q14<>"","Guest",""))) -> Match | D14: =IFERROR(MATCH($A14,'Match Log'!$K$3:$K$501,0)+2,"") -> 12 | E14: =IFERROR(MATCH($A14,'Tournament Log'!$O$4:$O$203,0)+3,"") | F14: =IF(C14="","",IF(C14="Match",INDEX('Match Log'!$B:$B,D14),IF(C14="Tournament",INDEX('Tournament Log'!$C:$C,E14),INDEX('Guest Log'!$B:$B,Q14)))) -> Andrew | G14: =IF(C14="","",IF(C14="Match",INDEX('Match Log'!$C:$C,D14),IF(C14="Tournament",INDEX('Tournament Log'!$B:$B,E14)&" (Phantom)",INDEX('Guest Log'!$H:$H,Q14)&" (Guest)"))) -> Brett | H14: {=IF(C14="","",IFERROR(LOOKUP(2,1/(($F$1:F13=F14)+($G$1:G13=F14)),IF($F$1:F13=F14,$N$1:N13,$O$1:O13)),1000))} -> 958 | I14: {=IF(C14="","",IF(C14="Tournament",INDEX('Tournament Log'!$J:$J,E14),IF(C14="Guest",IF(INDEX('Guest Log'!$I:$I,Q14)="",1000,INDEX('Guest Log'!$I:$I,Q14)),IFERROR(LOOKUP(2,1/(($F$1:F13=G14)+($G$1:G13=G14)),IF($F$1:F13=G14,$N$1:N13,$O$1:O13)),1000))))} -> 969 | J14: =IF(C14="","",1/(1+10^((I14-H14)/400))) -> 0.48417501 | K14: =IF(C14="","",IF(C14="Match",IF(INDEX('Match Log'!$D:$D,D14)="Win",1,IF(INDEX('Match Log'!$D:$D,D14)="Draw",0.5,0)),IF(C14="Tournament",INDEX('Tournament Log'!$K:$K,E14),IF(INDEX('Guest Log'!$C:$C,Q14)="Win",1,IF(INDEX('Guest Log'!$C:$C,Q14)="Draw",0.5,0))))) -> 1 | L14: =IF(C14="","",IF(C14="Match",32,IF(C14="Tournament",MIN(32*INDEX('Tournament Log'!$D:$D,E14),96),32))) -> 32 | M14: =IF(C14="","",ROUND(L14*(K14-J14),0)) -> 17 | N14: =IF(C14="","",H14+M14) -> 975 | O14: =IF(C14="","",IF(C14="Match",I14-M14,"")) -> 952 | P14: =IF(C14="Tournament",INDEX('Tournament Log'!$B:$B,E14),IF(C14="Guest","Guest: "&INDEX('Guest Log'!$H:$H,Q14),"")) | Q14: =IFERROR(MATCH($A14,'Guest Log'!$L$4:$L$203,0)+3,"")
A15: =14 -> 14 | B15: =IF(C15="","",IF(C15="Match",INDEX('Match Log'!$A:$A,D15),IF(C15="Tournament",INDEX('Tournament Log'!$A:$A,E15),INDEX('Guest Log'!$A:$A,Q15)))) -> 46209 | C15: =IF(D15<>"","Match",IF(E15<>"","Tournament",IF(Q15<>"","Guest",""))) -> Match | D15: =IFERROR(MATCH($A15,'Match Log'!$K$3:$K$501,0)+2,"") -> 13 | E15: =IFERROR(MATCH($A15,'Tournament Log'!$O$4:$O$203,0)+3,"") | F15: =IF(C15="","",IF(C15="Match",INDEX('Match Log'!$B:$B,D15),IF(C15="Tournament",INDEX('Tournament Log'!$C:$C,E15),INDEX('Guest Log'!$B:$B,Q15)))) -> Colin | G15: =IF(C15="","",IF(C15="Match",INDEX('Match Log'!$C:$C,D15),IF(C15="Tournament",INDEX('Tournament Log'!$B:$B,E15)&" (Phantom)",INDEX('Guest Log'!$H:$H,Q15)&" (Guest)"))) -> Miles | H15: {=IF(C15="","",IFERROR(LOOKUP(2,1/(($F$1:F14=F15)+($G$1:G14=F15)),IF($F$1:F14=F15,$N$1:N14,$O$1:O14)),1000))} -> 1013 | I15: {=IF(C15="","",IF(C15="Tournament",INDEX('Tournament Log'!$J:$J,E15),IF(C15="Guest",IF(INDEX('Guest Log'!$I:$I,Q15)="",1000,INDEX('Guest Log'!$I:$I,Q15)),IFERROR(LOOKUP(2,1/(($F$1:F14=G15)+($G$1:G14=G15)),IF($F$1:F14=G15,$N$1:N14,$O$1:O14)),1000))))} -> 1016 | J15: =IF(C15="","",1/(1+10^((I15-H15)/400))) -> 0.49568276 | K15: =IF(C15="","",IF(C15="Match",IF(INDEX('Match Log'!$D:$D,D15)="Win",1,IF(INDEX('Match Log'!$D:$D,D15)="Draw",0.5,0)),IF(C15="Tournament",INDEX('Tournament Log'!$K:$K,E15),IF(INDEX('Guest Log'!$C:$C,Q15)="Win",1,IF(INDEX('Guest Log'!$C:$C,Q15)="Draw",0.5,0))))) -> 0 | L15: =IF(C15="","",IF(C15="Match",32,IF(C15="Tournament",MIN(32*INDEX('Tournament Log'!$D:$D,E15),96),32))) -> 32 | M15: =IF(C15="","",ROUND(L15*(K15-J15),0)) -> -16 | N15: =IF(C15="","",H15+M15) -> 997 | O15: =IF(C15="","",IF(C15="Match",I15-M15,"")) -> 1032 | P15: =IF(C15="Tournament",INDEX('Tournament Log'!$B:$B,E15),IF(C15="Guest","Guest: "&INDEX('Guest Log'!$H:$H,Q15),"")) | Q15: =IFERROR(MATCH($A15,'Guest Log'!$L$4:$L$203,0)+3,"")
A16: =15 -> 15 | B16: =IF(C16="","",IF(C16="Match",INDEX('Match Log'!$A:$A,D16),IF(C16="Tournament",INDEX('Tournament Log'!$A:$A,E16),INDEX('Guest Log'!$A:$A,Q16)))) -> 46210 | C16: =IF(D16<>"","Match",IF(E16<>"","Tournament",IF(Q16<>"","Guest",""))) -> Match | D16: =IFERROR(MATCH($A16,'Match Log'!$K$3:$K$501,0)+2,"") -> 14 | E16: =IFERROR(MATCH($A16,'Tournament Log'!$O$4:$O$203,0)+3,"") | F16: =IF(C16="","",IF(C16="Match",INDEX('Match Log'!$B:$B,D16),IF(C16="Tournament",INDEX('Tournament Log'!$C:$C,E16),INDEX('Guest Log'!$B:$B,Q16)))) -> Andrew | G16: =IF(C16="","",IF(C16="Match",INDEX('Match Log'!$C:$C,D16),IF(C16="Tournament",INDEX('Tournament Log'!$B:$B,E16)&" (Phantom)",INDEX('Guest Log'!$H:$H,Q16)&" (Guest)"))) -> Colin | H16: {=IF(C16="","",IFERROR(LOOKUP(2,1/(($F$1:F15=F16)+($G$1:G15=F16)),IF($F$1:F15=F16,$N$1:N15,$O$1:O15)),1000))} -> 975 | I16: {=IF(C16="","",IF(C16="Tournament",INDEX('Tournament Log'!$J:$J,E16),IF(C16="Guest",IF(INDEX('Guest Log'!$I:$I,Q16)="",1000,INDEX('Guest Log'!$I:$I,Q16)),IFERROR(LOOKUP(2,1/(($F$1:F15=G16)+($G$1:G15=G16)),IF($F$1:F15=G16,$N$1:N15,$O$1:O15)),1000))))} -> 997 | J16: =IF(C16="","",1/(1+10^((I16-H16)/400))) -> 0.4683817 | K16: =IF(C16="","",IF(C16="Match",IF(INDEX('Match Log'!$D:$D,D16)="Win",1,IF(INDEX('Match Log'!$D:$D,D16)="Draw",0.5,0)),IF(C16="Tournament",INDEX('Tournament Log'!$K:$K,E16),IF(INDEX('Guest Log'!$C:$C,Q16)="Win",1,IF(INDEX('Guest Log'!$C:$C,Q16)="Draw",0.5,0))))) -> 0 | L16: =IF(C16="","",IF(C16="Match",32,IF(C16="Tournament",MIN(32*INDEX('Tournament Log'!$D:$D,E16),96),32))) -> 32 | M16: =IF(C16="","",ROUND(L16*(K16-J16),0)) -> -15 | N16: =IF(C16="","",H16+M16) -> 960 | O16: =IF(C16="","",IF(C16="Match",I16-M16,"")) -> 1012 | P16: =IF(C16="Tournament",INDEX('Tournament Log'!$B:$B,E16),IF(C16="Guest","Guest: "&INDEX('Guest Log'!$H:$H,Q16),"")) | Q16: =IFERROR(MATCH($A16,'Guest Log'!$L$4:$L$203,0)+3,"")
A17: =16 -> 16 | B17: =IF(C17="","",IF(C17="Match",INDEX('Match Log'!$A:$A,D17),IF(C17="Tournament",INDEX('Tournament Log'!$A:$A,E17),INDEX('Guest Log'!$A:$A,Q17)))) -> 46212 | C17: =IF(D17<>"","Match",IF(E17<>"","Tournament",IF(Q17<>"","Guest",""))) -> Match | D17: =IFERROR(MATCH($A17,'Match Log'!$K$3:$K$501,0)+2,"") -> 15 | E17: =IFERROR(MATCH($A17,'Tournament Log'!$O$4:$O$203,0)+3,"") | F17: =IF(C17="","",IF(C17="Match",INDEX('Match Log'!$B:$B,D17),IF(C17="Tournament",INDEX('Tournament Log'!$C:$C,E17),INDEX('Guest Log'!$B:$B,Q17)))) -> John | G17: =IF(C17="","",IF(C17="Match",INDEX('Match Log'!$C:$C,D17),IF(C17="Tournament",INDEX('Tournament Log'!$B:$B,E17)&" (Phantom)",INDEX('Guest Log'!$H:$H,Q17)&" (Guest)"))) -> Andrew | H17: {=IF(C17="","",IFERROR(LOOKUP(2,1/(($F$1:F16=F17)+($G$1:G16=F17)),IF($F$1:F16=F17,$N$1:N16,$O$1:O16)),1000))} -> 1038 | I17: {=IF(C17="","",IF(C17="Tournament",INDEX('Tournament Log'!$J:$J,E17),IF(C17="Guest",IF(INDEX('Guest Log'!$I:$I,Q17)="",1000,INDEX('Guest Log'!$I:$I,Q17)),IFERROR(LOOKUP(2,1/(($F$1:F16=G17)+($G$1:G16=G17)),IF($F$1:F16=G17,$N$1:N16,$O$1:O16)),1000))))} -> 1000 | J17: =IF(C17="","",1/(1+10^((I17-H17)/400))) -> 0.55446937 | K17: =IF(C17="","",IF(C17="Match",IF(INDEX('Match Log'!$D:$D,D17)="Win",1,IF(INDEX('Match Log'!$D:$D,D17)="Draw",0.5,0)),IF(C17="Tournament",INDEX('Tournament Log'!$K:$K,E17),IF(INDEX('Guest Log'!$C:$C,Q17)="Win",1,IF(INDEX('Guest Log'!$C:$C,Q17)="Draw",0.5,0))))) -> 1 | L17: =IF(C17="","",IF(C17="Match",32,IF(C17="Tournament",MIN(32*INDEX('Tournament Log'!$D:$D,E17),96),32))) -> 32 | M17: =IF(C17="","",ROUND(L17*(K17-J17),0)) -> 14 | N17: =IF(C17="","",H17+M17) -> 1052 | O17: =IF(C17="","",IF(C17="Match",I17-M17,"")) -> 986 | P17: =IF(C17="Tournament",INDEX('Tournament Log'!$B:$B,E17),IF(C17="Guest","Guest: "&INDEX('Guest Log'!$H:$H,Q17),"")) | Q17: =IFERROR(MATCH($A17,'Guest Log'!$L$4:$L$203,0)+3,"")
